<?xml version="1.0" ?>
<!-- =================================================================================== -->
<!-- |    This document was autogenerated by xacro from urdf/4weel_version2.xacro      | -->
<!-- |    EDITING THIS FILE BY HAND IS NOT RECOMMENDED                                 | -->
<!-- =================================================================================== -->
<robot xmlns:xacro="http://www.ros.org/wiki/xacro" name="4weel_version2">
  <material name="silver">
    <color rgba="0.700 0.700 0.700 1.000"/>
  </material>
  <transmission name="Revolute 8_tran">
    <type>transmission_interface/SimpleTransmission</type>
    <joint name="Revolute 8">
      <hardwareInterface>hardware_interface/EffortJointInterface</hardwareInterface>
    </joint>
    <actuator name="Revolute 8_actr">
      <hardwareInterface>hardware_interface/EffortJointInterface</hardwareInterface>
      <mechanicalReduction>1</mechanicalReduction>
    </actuator>
  </transmission>
  <transmission name="Revolute 9_tran">
    <type>transmission_interface/SimpleTransmission</type>
    <joint name="Revolute 9">
      <hardwareInterface>hardware_interface/EffortJointInterface</hardwareInterface>
    </joint>
    <actuator name="Revolute 9_actr">
      <hardwareInterface>hardware_interface/EffortJointInterface</hardwareInterface>
      <mechanicalReduction>1</mechanicalReduction>
    </actuator>
  </transmission>
  <transmission name="Revolute 10_tran">
    <type>transmission_interface/SimpleTransmission</type>
    <joint name="Revolute 10">
      <hardwareInterface>hardware_interface/EffortJointInterface</hardwareInterface>
    </joint>
    <actuator name="Revolute 10_actr">
      <hardwareInterface>hardware_interface/EffortJointInterface</hardwareInterface>
      <mechanicalReduction>1</mechanicalReduction>
    </actuator>
  </transmission>
  <transmission name="Revolute 11_tran">
    <type>transmission_interface/SimpleTransmission</type>
    <joint name="Revolute 11">
      <hardwareInterface>hardware_interface/EffortJointInterface</hardwareInterface>
    </joint>
    <actuator name="Revolute 11_actr">
      <hardwareInterface>hardware_interface/EffortJointInterface</hardwareInterface>
      <mechanicalReduction>1</mechanicalReduction>
    </actuator>
  </transmission>
  <gazebo>
    <plugin name="control" filename="libgazebo_ros_control.so"/>
  </gazebo>
  <gazebo reference="base_link">
    <material>Gazebo/Silver</material>
    <mu1>0.2</mu1>
    <mu2>0.2</mu2>
    <selfCollide>true</selfCollide>
    <gravity>true</gravity>
  </gazebo>
  <gazebo reference="lidar_v1_1">
    <material>Gazebo/Silver</material>
    <mu1>0.2</mu1>
    <mu2>0.2</mu2>
    <selfCollide>true</selfCollide>
  </gazebo>
  <gazebo reference="back_left_1">
    <material>Gazebo/Silver</material>
    <mu1>0.2</mu1>
    <mu2>0.2</mu2>
    <selfCollide>true</selfCollide>
  </gazebo>
  <gazebo reference="back_right_1">
    <material>Gazebo/Silver</material>
    <mu1>0.2</mu1>
    <mu2>0.2</mu2>
    <selfCollide>true</selfCollide>
  </gazebo>
  <gazebo reference="front_left_1">
    <material>Gazebo/Silver</material>
    <mu1>0.2</mu1>
    <mu2>0.2</mu2>
    <selfCollide>true</selfCollide>
  </gazebo>
  <gazebo reference="front_right_1">
    <material>Gazebo/Silver</material>
    <mu1>0.2</mu1>
    <mu2>0.2</mu2>
    <selfCollide>true</selfCollide>
  </gazebo>
  <link name="base_link">
    <inertial>
      <origin xyz="-0.0026827952129199395 -9.24237718342667e-06 0.050011490590469505" rpy="0 0 0"/>
      <mass value="11.135828149573104"/>
      <inertia ixx="0.069638" iyy="0.133325" izz="0.14446" ixy="1.3e-05" iyz="4e-06" ixz="0.010205"/>
    </inertial>
    <visual>
      <origin xyz="0 0 0" rpy="0 0 0"/>
      <geometry>
        <mesh filename="package://4weel_version2_description/meshes/base_link.stl" scale="0.001 0.001 0.001"/>
      </geometry>
      <material name="silver"/>
    </visual>
    <collision>
      <origin xyz="0 0 0" rpy="0 0 0"/>
      <geometry>
        <mesh filename="package://4weel_version2_description/meshes/base_link.stl" scale="0.001 0.001 0.001"/>
      </geometry>
    </collision>
  </link>
  <link name="lidar_v1_1">
    <inertial>
      <origin xyz="0.09999999899417161 -4.220056531838944e-18 0.009858499938735416" rpy="0 0 0"/>
      <mass value="0.5286905929941375"/>
      <inertia ixx="0.000159" iyy="0.000159" izz="0.000284" ixy="-0.0" iyz="0.0" ixz="-0.0"/>
    </inertial>
    <visual>
      <origin xyz="0.0675 -0.0 -0.165" rpy="0 0 0"/>
      <geometry>
        <mesh filename="package://4weel_version2_description/meshes/lidar_v1_1.stl" scale="0.001 0.001 0.001"/>
      </geometry>
      <material name="silver"/>
    </visual>
    <collision>
      <origin xyz="0.0675 -0.0 -0.165" rpy="0 0 0"/>
      <geometry>
        <mesh filename="package://4weel_version2_description/meshes/lidar_v1_1.stl" scale="0.001 0.001 0.001"/>
      </geometry>
    </collision>
  </link>
  <link name="back_left_1">
    <inertial>
      <origin xyz="-2.0116567023276133e-09 -0.015000000000000013 1.0408340855860843e-17" rpy="0 0 0"/>
      <mass value="1.1837521118726324"/>
      <inertia ixx="0.000562" iyy="0.000947" izz="0.000562" ixy="-0.0" iyz="0.0" ixz="-0.0"/>
    </inertial>
    <visual>
      <origin xyz="0.1375 0.1175 -0.0225" rpy="0 0 0"/>
      <geometry>
        <mesh filename="package://4weel_version2_description/meshes/back_left_1.stl" scale="0.001 0.001 0.001"/>
      </geometry>
      <material name="silver"/>
    </visual>
    <collision>
      <origin xyz="0.1375 0.1175 -0.0225" rpy="0 0 0"/>
      <geometry>
        <mesh filename="package://4weel_version2_description/meshes/back_left_1.stl" scale="0.001 0.001 0.001"/>
      </geometry>
    </collision>
  </link>
  <link name="back_right_1">
    <inertial>
      <origin xyz="-2.01165678559434e-09 0.01499999999999993 0.0" rpy="0 0 0"/>
      <mass value="1.1837521118726324"/>
      <inertia ixx="0.000562" iyy="0.000947" izz="0.000562" ixy="0.0" iyz="-0.0" ixz="0.0"/>
    </inertial>
    <visual>
      <origin xyz="0.1375 -0.1175 -0.0225" rpy="0 0 0"/>
      <geometry>
        <mesh filename="package://4weel_version2_description/meshes/back_right_1.stl" scale="0.001 0.001 0.001"/>
      </geometry>
      <material name="silver"/>
    </visual>
    <collision>
      <origin xyz="0.1375 -0.1175 -0.0225" rpy="0 0 0"/>
      <geometry>
        <mesh filename="package://4weel_version2_description/meshes/back_right_1.stl" scale="0.001 0.001 0.001"/>
      </geometry>
    </collision>
  </link>
  <link name="front_left_1">
    <inertial>
      <origin xyz="-2.0116567578387645e-09 0.015000000000000013 3.469446951953614e-17" rpy="0 0 0"/>
      <mass value="1.1837521118726333"/>
      <inertia ixx="0.000562" iyy="0.000947" izz="0.000562" ixy="0.0" iyz="0.0" ixz="-0.0"/>
    </inertial>
    <visual>
      <origin xyz="-0.1575 -0.1175 -0.0225" rpy="0 0 0"/>
      <geometry>
        <mesh filename="package://4weel_version2_description/meshes/front_left_1.stl" scale="0.001 0.001 0.001"/>
      </geometry>
      <material name="silver"/>
    </visual>
    <collision>
      <origin xyz="-0.1575 -0.1175 -0.0225" rpy="0 0 0"/>
      <geometry>
        <mesh filename="package://4weel_version2_description/meshes/front_left_1.stl" scale="0.001 0.001 0.001"/>
      </geometry>
    </collision>
  </link>
  <link name="front_right_1">
    <inertial>
      <origin xyz="-2.0116567578387645e-09 -0.015000000000000013 0.0" rpy="0 0 0"/>
      <mass value="1.1837521118726337"/>
      <inertia ixx="0.000562" iyy="0.000947" izz="0.000562" ixy="0.0" iyz="-0.0" ixz="0.0"/>
    </inertial>
    <visual>
      <origin xyz="-0.1575 0.1175 -0.0225" rpy="0 0 0"/>
      <geometry>
        <mesh filename="package://4weel_version2_description/meshes/front_right_1.stl" scale="0.001 0.001 0.001"/>
      </geometry>
      <material name="silver"/>
    </visual>
    <collision>
      <origin xyz="-0.1575 0.1175 -0.0225" rpy="0 0 0"/>
      <geometry>
        <mesh filename="package://4weel_version2_description/meshes/front_right_1.stl" scale="0.001 0.001 0.001"/>
      </geometry>
    </collision>
  </link>
  <joint name="Rigid 3" type="fixed">
    <origin xyz="-0.0675 0.0 0.165" rpy="0 0 0"/>
    <parent link="base_link"/>
    <child link="lidar_v1_1"/>
  </joint>
  <joint name="Revolute 8" type="continuous">
    <origin xyz="-0.1375 -0.1175 0.0225" rpy="0 0 0"/>
    <parent link="base_link"/>
    <child link="back_left_1"/>
    <axis xyz="0.0 -1.0 0.0"/>
  </joint>
  <joint name="Revolute 9" type="continuous">
    <origin xyz="-0.1375 0.1175 0.0225" rpy="0 0 0"/>
    <parent link="base_link"/>
    <child link="back_right_1"/>
    <axis xyz="0.0 1.0 0.0"/>
  </joint>
  <joint name="Revolute 10" type="continuous">
    <origin xyz="0.1575 0.1175 0.0225" rpy="0 0 0"/>
    <parent link="base_link"/>
    <child link="front_left_1"/>
    <axis xyz="0.0 1.0 0.0"/>
  </joint>
  <joint name="Revolute 11" type="continuous">
    <origin xyz="0.1575 -0.1175 0.0225" rpy="0 0 0"/>
    <parent link="base_link"/>
    <child link="front_right_1"/>
    <axis xyz="0.0 -1.0 0.0"/>
  </joint>
</robot>
